<?xml version="1.0" encoding="UTF-8"?>
<testng-results ignored="0" total="1" passed="0" failed="1" skipped="0">
  <reporter-output>
  </reporter-output>
  <suite started-at="2023-09-06T11:48:27 IST" name="Default suite" finished-at="2023-09-06T11:48:27 IST" duration-ms="145">
    <groups>
    </groups>
    <test started-at="2023-09-06T11:48:27 IST" name="Default test" finished-at="2023-09-06T11:48:27 IST" duration-ms="145">
      <class name="dataDrivenTesting.ReadDataFromDataBaseTest">
        <test-method signature="test()[pri:0, instance:dataDrivenTesting.ReadDataFromDataBaseTest@1fa268de]" started-at="2023-09-06T11:48:27 IST" name="test" finished-at="2023-09-06T11:48:27 IST" duration-ms="114" status="FAIL">
          <exception class="com.mysql.cj.jdbc.exceptions.CommunicationsException">
            <message>
              <![CDATA[Communications link failure

The last packet sent successfully to the server was 0 milliseconds ago. The driver has not received any packets from the server.]]>
            </message>
            <full-stacktrace>
              <![CDATA[com.mysql.cj.jdbc.exceptions.CommunicationsException: Communications link failure

The last packet sent successfully to the server was 0 milliseconds ago. The driver has not received any packets from the server.
at com.mysql.cj.jdbc.exceptions.SQLError.createCommunicationsException(SQLError.java:175)
at com.mysql.cj.jdbc.exceptions.SQLExceptionsMapping.translateException(SQLExceptionsMapping.java:64)
at com.mysql.cj.jdbc.ConnectionImpl.createNewIO(ConnectionImpl.java:819)
at com.mysql.cj.jdbc.ConnectionImpl.<init>(ConnectionImpl.java:440)
at com.mysql.cj.jdbc.ConnectionImpl.getInstance(ConnectionImpl.java:239)
at com.mysql.cj.jdbc.NonRegisteringDriver.connect(NonRegisteringDriver.java:188)
at java.sql/java.sql.DriverManager.getConnection(DriverManager.java:683)
at java.sql/java.sql.DriverManager.getConnection(DriverManager.java:230)
at dataDrivenTesting.ReadDataFromDataBaseTest.test(ReadDataFromDataBaseTest.java:20)
at java.base/jdk.internal.reflect.DirectMethodHandleAccessor.invoke(DirectMethodHandleAccessor.java:104)
at java.base/java.lang.reflect.Method.invoke(Method.java:577)
at org.testng.internal.invokers.MethodInvocationHelper.invokeMethod(MethodInvocationHelper.java:139)
at org.testng.internal.invokers.TestInvoker.invokeMethod(TestInvoker.java:677)
at org.testng.internal.invokers.TestInvoker.invokeTestMethod(TestInvoker.java:221)
at org.testng.internal.invokers.MethodRunner.runInSequence(MethodRunner.java:50)
at org.testng.internal.invokers.TestInvoker$MethodInvocationAgent.invoke(TestInvoker.java:969)
at org.testng.internal.invokers.TestInvoker.invokeTestMethods(TestInvoker.java:194)
at org.testng.internal.invokers.TestMethodWorker.invokeTestMethods(TestMethodWorker.java:148)
at org.testng.internal.invokers.TestMethodWorker.run(TestMethodWorker.java:128)
at java.base/java.util.ArrayList.forEach(ArrayList.java:1511)
at org.testng.TestRunner.privateRun(TestRunner.java:829)
at org.testng.TestRunner.run(TestRunner.java:602)
at org.testng.SuiteRunner.runTest(SuiteRunner.java:437)
at org.testng.SuiteRunner.runSequentially(SuiteRunner.java:431)
at org.testng.SuiteRunner.privateRun(SuiteRunner.java:391)
at org.testng.SuiteRunner.run(SuiteRunner.java:330)
at org.testng.SuiteRunnerWorker.runSuite(SuiteRunnerWorker.java:52)
at org.testng.SuiteRunnerWorker.run(SuiteRunnerWorker.java:95)
at org.testng.TestNG.runSuitesSequentially(TestNG.java:1256)
at org.testng.TestNG.runSuitesLocally(TestNG.java:1176)
at org.testng.TestNG.runSuites(TestNG.java:1099)
at org.testng.TestNG.run(TestNG.java:1067)
at org.testng.remote.AbstractRemoteTestNG.run(AbstractRemoteTestNG.java:115)
at org.testng.remote.RemoteTestNG.initAndRun(RemoteTestNG.java:251)
at org.testng.remote.RemoteTestNG.main(RemoteTestNG.java:77)
Caused by: com.mysql.cj.exceptions.CJCommunicationsException: Communications link failure

The last packet sent successfully to the server was 0 milliseconds ago. The driver has not received any packets from the server.
at java.base/jdk.internal.reflect.DirectConstructorHandleAccessor.newInstance(DirectConstructorHandleAccessor.java:67)
at java.base/java.lang.reflect.Constructor.newInstanceWithCaller(Constructor.java:499)
at java.base/java.lang.reflect.Constructor.newInstance(Constructor.java:483)
at com.mysql.cj.exceptions.ExceptionFactory.createException(ExceptionFactory.java:62)
at com.mysql.cj.exceptions.ExceptionFactory.createException(ExceptionFactory.java:105)
at com.mysql.cj.exceptions.ExceptionFactory.createException(ExceptionFactory.java:150)
at com.mysql.cj.exceptions.ExceptionFactory.createCommunicationsException(ExceptionFactory.java:166)
at com.mysql.cj.protocol.a.NativeSocketConnection.connect(NativeSocketConnection.java:89)
at com.mysql.cj.NativeSession.connect(NativeSession.java:121)
at com.mysql.cj.jdbc.ConnectionImpl.connectOneTryOnly(ConnectionImpl.java:939)
at com.mysql.cj.jdbc.ConnectionImpl.createNewIO(ConnectionImpl.java:809)
... 32 more
Caused by: java.net.ConnectException: Connection refused: connect
at java.base/sun.nio.ch.Net.connect0(Native Method)
at java.base/sun.nio.ch.Net.connect(Net.java:579)
at java.base/sun.nio.ch.Net.connect(Net.java:568)
at java.base/sun.nio.ch.NioSocketImpl.connect(NioSocketImpl.java:585)
at java.base/java.net.SocksSocketImpl.connect(SocksSocketImpl.java:327)
at java.base/java.net.Socket.connect(Socket.java:633)
at com.mysql.cj.protocol.StandardSocketFactory.connect(StandardSocketFactory.java:153)
at com.mysql.cj.protocol.a.NativeSocketConnection.connect(NativeSocketConnection.java:63)
... 35 more
]]>
            </full-stacktrace>
          </exception> <!-- com.mysql.cj.jdbc.exceptions.CommunicationsException -->
          <reporter-output>
          </reporter-output>
        </test-method> <!-- test -->
      </class> <!-- dataDrivenTesting.ReadDataFromDataBaseTest -->
    </test> <!-- Default test -->
  </suite> <!-- Default suite -->
</testng-results>
